Workbook
Name Score_Prediction_ABL: HOBL!$G$35
Name Score_Prediction_ABL_Active: HOBL!$G$37
Name Score_Prediction_HoBL: HOBL!$G$34
Name Score_Prediction_HoBL_Active: HOBL!$G$29
Name Score_Prediction_HoBL_ScreenOff: HOBL!$G$30
Name Score_Prediction_LAP: HOBL!$G$38
Name Score_Prediction_LVP: HOBL!$G$39
Name Score_Prediction_Standby: HOBL!$G$31
Name Score_Prediction_Talktime: HOBL!$G$33
Name Variable_Battery_Active: HOBL!$G$26
Name Variable_Battery_Available: HOBL!$G$23
Name Variable_Battery_FCC: HOBL!$G$20
Name Variable_Battery_Minimum: HOBL!#REF!
Name Variable_Battery_Standby: HOBL!$G$24

Sheet HOBL
A1: 8
A3: Scorecard | D3: Day in Life | E3: HoBL | G3: Battery Use | K3: Scenario Measurement Warnings
B4: Category | C4: Category Power | D4: "DiL" Time | E4: "System On" | F4: Weighted Power | G4: Battery Draw | H4: Energy Usage
C5: (W) | D5: (hrs) | E5: (%) | F5: (W) | G5: (%) | H5: (Whr)
B6: Standby | C6: =VLOOKUP(Classic_HoBL_Summary6[[#This Row],[Category]],Classic_Categories_Measured[[Categories]:[Category Power (W)]], 4, FALSE) -> 0 | D6: =$D$7*(Classic_HoBL_Summary6[[#This Row],["System On"]]/$E$7) -> 12.6 | E6: 0.7 | F6: =E6*C6 -> 0 | G6: =F6/F$18 -> #DIV/0! | H6: =G6*G$23 -> #DIV/0! | L6: HoBL/ABL Score | M6: Scenario | N6: Category | O6: Runs Missing | P6: Runs Required | Q6: StDv | X6: Counts Required | Y6: Data Valid | Z6: Run Count
B7: Screen Off - Totals | D7: =18*Classic_HoBL_Summary6[[#This Row],["System On"]] -> 12.6 | E7: 0.7 | F7: =SUM(F6:F6) -> 0 | G7: =SUM(G6:G6) -> #DIV/0! | H7: =SUM(H6:H6) -> #DIV/0! | L7: =IF(X7=0, "Not Required", IF(Y7 < X7, "Absent Data", "Present")) -> Absent Data | M7: facebook_1s | N7: Social | O7: =MAX(0, P7-Z7) -> 3 | P7: 3 | Q7: {=IFERROR(OFFSET(INDIRECT("Power."&M7&"!A1"),MATCH("Total Power (W)",INDIRECT("Power."&M7&"!A:A"),0)-1,MATCH("Std Dev",INDIRECT("Power."&M7&"!1:1"),0)-1),"")} | X7: =COUNTIFS(Classic_Scenarios_Measured[Scenario Weight], ">1%", Classic_Scenarios_Measured[Scenario], HOBL!M7) -> 1 | Y7: =COUNTIFS(Classic_Scenarios_Measured[Scorecard (W)], ">.001", Classic_Scenarios_Measured[Scenario], HOBL!M7) -> 0 | Z7: =MAX(0, COUNTA(INDIRECT("Power."&M7&"!B1:BA1"))-2) -> 0
B8: Web | C8: =VLOOKUP(Classic_HoBL_Summary6[[#This Row],[Category]],Classic_Categories_Measured[[Categories]:[Category Power (W)]], 4, FALSE) -> 0 | D8: =$D$17*Classic_HoBL_Summary6[[#This Row],["System On"]]/$E$17 -> 1.35 | E8: 0.075 | F8: =E8*C8 -> 0 | G8: =F8/F$18 -> #DIV/0! | H8: =G8*G$23 -> #DIV/0! | L8: =IF(X8=0, "Not Required", IF(Y8 < X8, "Absent Data", "Present")) -> Not Required | M8: instagram_1s | N8: Social | O8: =MAX(0, P8-Z8) -> 0 | P8: 0 | Q8: {=IFERROR(OFFSET(INDIRECT("Power."&M8&"!A1"),MATCH("Total Power (W)",INDIRECT("Power."&M8&"!A:A"),0)-1,MATCH("Std Dev",INDIRECT("Power."&M8&"!1:1"),0)-1),"")} | X8: =COUNTIFS(Classic_Scenarios_Measured[Scenario Weight], ">1%", Classic_Scenarios_Measured[Scenario], HOBL!M8) -> 0 | Y8: =COUNTIFS(Classic_Scenarios_Measured[Scorecard (W)], ">.001", Classic_Scenarios_Measured[Scenario], HOBL!M8) -> 0 | Z8: =MAX(0, COUNTA(INDIRECT("Power."&M8&"!B1:BA1"))-2) -> 0
B9: Productivity | C9: =VLOOKUP(Classic_HoBL_Summary6[[#This Row],[Category]],Classic_Categories_Measured[[Categories]:[Category Power (W)]], 4, FALSE) -> 0 | D9: =$D$17*Classic_HoBL_Summary6[[#This Row],["System On"]]/$E$17 -> 0.81 | E9: 0.045 | F9: =E9*C9 -> 0 | G9: =F9/F$18 -> #DIV/0! | H9: =G9*G$23 -> #DIV/0! | L9: =IF(X9=0, "Not Required", IF(Y9 < X9, "Absent Data", "Present")) -> Absent Data | M9: instagram_2s | N9: Social | O9: =MAX(0, P9-Z9) -> 3 | P9: 3 | Q9: {=IFERROR(OFFSET(INDIRECT("Power."&M9&"!A1"),MATCH("Total Power (W)",INDIRECT("Power."&M9&"!A:A"),0)-1,MATCH("Std Dev",INDIRECT("Power."&M9&"!1:1"),0)-1),"")} | X9: =COUNTIFS(Classic_Scenarios_Measured[Scenario Weight], ">1%", Classic_Scenarios_Measured[Scenario], HOBL!M9) -> 1 | Y9: =COUNTIFS(Classic_Scenarios_Measured[Scorecard (W)], ">.001", Classic_Scenarios_Measured[Scenario], HOBL!M9) -> 0 | Z9: =MAX(0, COUNTA(INDIRECT("Power."&M9&"!B1:BA1"))-2) -> 0
B10: Communication | C10: =VLOOKUP(Classic_HoBL_Summary6[[#This Row],[Category]],Classic_Categories_Measured[[Categories]:[Category Power (W)]], 4, FALSE) -> 0 | D10: =$D$17*Classic_HoBL_Summary6[[#This Row],["System On"]]/$E$17 -> 0.54 | E10: 0.03 | F10: =E10*C10 -> 0 | G10: =F10/F$18 -> #DIV/0! | H10: =G10*G$23 -> #DIV/0! | L10: =IF(X10=0, "Not Required", IF(Y10 < X10, "Absent Data", "Present")) -> Absent Data | M10: edge_1s | N10: Web | O10: =MAX(0, P10-Z10) -> 3 | P10: 3 | Q10: {=IFERROR(OFFSET(INDIRECT("Power."&M10&"!A1"),MATCH("Total Power (W)",INDIRECT("Power."&M10&"!A:A"),0)-1,MATCH("Std Dev",INDIRECT("Power."&M10&"!1:1"),0)-1),"")} | X10: =COUNTIFS(Classic_Scenarios_Measured[Scenario Weight], ">1%", Classic_Scenarios_Measured[Scenario], HOBL!M10) -> 1 | Y10: =COUNTIFS(Classic_Scenarios_Measured[Scorecard (W)], ">.001", Classic_Scenarios_Measured[Scenario], HOBL!M10) -> 0 | Z10: =MAX(0, COUNTA(INDIRECT("Power."&M10&"!B1:BA1"))-2) -> 0
B11: Gaming | C11: =VLOOKUP(Classic_HoBL_Summary6[[#This Row],[Category]],Classic_Categories_Measured[[Categories]:[Category Power (W)]], 4, FALSE) -> 0 | D11: =$D$17*Classic_HoBL_Summary6[[#This Row],["System On"]]/$E$17 -> 0.54 | E11: 0.03 | F11: =E11*C11 -> 0 | G11: =F11/F$18 -> #DIV/0! | H11: =G11*G$23 -> #DIV/0! | L11: =IF(X11=0, "Not Required", IF(Y11 < X11, "Absent Data", "Present")) -> Absent Data | M11: edge_fb_2s | N11: Web | O11: =MAX(0, P11-Z11) -> 3 | P11: 3 | Q11: {=IFERROR(OFFSET(INDIRECT("Power."&M11&"!A1"),MATCH("Total Power (W)",INDIRECT("Power."&M11&"!A:A"),0)-1,MATCH("Std Dev",INDIRECT("Power."&M11&"!1:1"),0)-1),"")} | X11: =COUNTIFS(Classic_Scenarios_Measured[Scenario Weight], ">1%", Classic_Scenarios_Measured[Scenario], HOBL!M11) -> 1 | Y11: =COUNTIFS(Classic_Scenarios_Measured[Scorecard (W)], ">.001", Classic_Scenarios_Measured[Scenario], HOBL!M11) -> 0 | Z11: =MAX(0, COUNTA(INDIRECT("Power."&M11&"!B1:BA1"))-2) -> 0
B12: Entertainment | C12: =VLOOKUP(Classic_HoBL_Summary6[[#This Row],[Category]],Classic_Categories_Measured[[Categories]:[Category Power (W)]], 4, FALSE) -> 0 | D12: =$D$17*Classic_HoBL_Summary6[[#This Row],["System On"]]/$E$17 -> 0.54 | E12: 0.03 | F12: =E12*C12 -> 0 | G12: =F12/F$18 -> #DIV/0! | H12: =G12*G$23 -> #DIV/0! | L12: =IF(X12=0, "Not Required", IF(Y12 < X12, "Absent Data", "Present")) -> Not Required | M12: chrome_1s | N12: Web | O12: =MAX(0, P12-Z12) -> 0 | P12: 0 | Q12: {=IFERROR(OFFSET(INDIRECT("Power."&M12&"!A1"),MATCH("Total Power (W)",INDIRECT("Power."&M12&"!A:A"),0)-1,MATCH("Std Dev",INDIRECT("Power."&M12&"!1:1"),0)-1),"")} | X12: =COUNTIFS(Classic_Scenarios_Measured[Scenario Weight], ">1%", Classic_Scenarios_Measured[Scenario], HOBL!M12) -> 0 | Y12: =COUNTIFS(Classic_Scenarios_Measured[Scorecard (W)], ">.001", Classic_Scenarios_Measured[Scenario], HOBL!M12) -> 0 | Z12: =MAX(0, COUNTA(INDIRECT("Power."&M12&"!B1:BA1"))-2) -> 0
B13: System | C13: =VLOOKUP(Classic_HoBL_Summary6[[#This Row],[Category]],Classic_Categories_Measured[[Categories]:[Category Power (W)]], 4, FALSE) -> 0 | D13: =$D$17*Classic_HoBL_Summary6[[#This Row],["System On"]]/$E$17 -> 0.27 | E13: 0.015 | F13: =E13*C13 -> 0 | G13: =F13/F$18 -> #DIV/0! | H13: =G13*G$23 -> #DIV/0! | L13: =IF(X13=0, "Not Required", IF(Y13 < X13, "Absent Data", "Present")) -> Not Required | M13: local_video_1s | N13: Entertainment | O13: =MAX(0, P13-Z13) -> 5 | P13: 5 | Q13: {=IFERROR(OFFSET(INDIRECT("Power."&M13&"!A1"),MATCH("Total Power (W)",INDIRECT("Power."&M13&"!A:A"),0)-1,MATCH("Std Dev",INDIRECT("Power."&M13&"!1:1"),0)-1),"")} | X13: =COUNTIFS(Classic_Scenarios_Measured[Scenario Weight], ">1%", Classic_Scenarios_Measured[Scenario], HOBL!M13) -> 0 | Y13: =COUNTIFS(Classic_Scenarios_Measured[Scorecard (W)], ">.001", Classic_Scenarios_Measured[Scenario], HOBL!M13) -> 0 | Z13: =MAX(0, COUNTA(INDIRECT("Power."&M13&"!B1:BA1"))-2) -> 0
B14: Smartphone | C14: =VLOOKUP(Classic_HoBL_Summary6[[#This Row],[Category]],Classic_Categories_Measured[[Categories]:[Category Power (W)]], 4, FALSE) -> 0 | D14: =$D$17*Classic_HoBL_Summary6[[#This Row],["System On"]]/$E$17 -> 0.27 | E14: 0.015 | F14: =E14*C14 -> 0 | G14: =F14/F$18 -> #DIV/0! | H14: =G14*G$23 -> #DIV/0! | L14: =IF(X14=0, "Not Required", IF(Y14 < X14, "Absent Data", "Present")) -> Not Required | M14: local_video_apm_1s | N14: Entertainment | O14: =MAX(0, P14-Z14) -> 0 | P14: 0 | Q14: {=IFERROR(OFFSET(INDIRECT("Power."&M14&"!A1"),MATCH("Total Power (W)",INDIRECT("Power."&M14&"!A:A"),0)-1,MATCH("Std Dev",INDIRECT("Power."&M14&"!1:1"),0)-1),"")} | X14: =COUNTIFS(Classic_Scenarios_Measured[Scenario Weight], ">1%", Classic_Scenarios_Measured[Scenario], HOBL!M14) -> 0 | Y14: =COUNTIFS(Classic_Scenarios_Measured[Scorecard (W)], ">.001", Classic_Scenarios_Measured[Scenario], HOBL!M14) -> 0 | Z14: =MAX(0, COUNTA(INDIRECT("Power."&M14&"!B1:BA1"))-2) -> 0
B15: Social | C15: =VLOOKUP(Classic_HoBL_Summary6[[#This Row],[Category]],Classic_Categories_Measured[[Categories]:[Category Power (W)]], 4, FALSE) -> 0 | D15: =$D$17*Classic_HoBL_Summary6[[#This Row],["System On"]]/$E$17 -> 1.08 | E15: 0.06 | F15: =E15*C15 -> 0 | G15: =F15/F$18 -> #DIV/0! | H15: =G15*G$23 -> #DIV/0! | L15: =IF(X15=0, "Not Required", IF(Y15 < X15, "Absent Data", "Present")) -> Absent Data | M15: spotify_0s | N15: Entertainment | O15: =MAX(0, P15-Z15) -> 3 | P15: 3 | Q15: {=IFERROR(OFFSET(INDIRECT("Power."&M15&"!A1"),MATCH("Total Power (W)",INDIRECT("Power."&M15&"!A:A"),0)-1,MATCH("Std Dev",INDIRECT("Power."&M15&"!1:1"),0)-1),"")} | X15: =COUNTIFS(Classic_Scenarios_Measured[Scenario Weight], ">1%", Classic_Scenarios_Measured[Scenario], HOBL!M15) -> 1 | Y15: =COUNTIFS(Classic_Scenarios_Measured[Scorecard (W)], ">.001", Classic_Scenarios_Measured[Scenario], HOBL!M15) -> 0 | Z15: =MAX(0, COUNTA(INDIRECT("Power."&M15&"!B1:BA1"))-2) -> 0
B16: Idle | C16: =VLOOKUP(Classic_HoBL_Summary6[[#This Row],[Category]],Classic_Categories_Measured[[Categories]:[Category Power (W)]], 4, FALSE) -> 0 | D16: =$D$17*Classic_HoBL_Summary6[[#This Row],["System On"]]/$E$17 -> 0 | E16: 0 | F16: =E16*C16 -> 0 | G16: =F16/F$18 -> #DIV/0! | H16: =G16*G$23 -> #DIV/0! | L16: =IF(X16=0, "Not Required", IF(Y16 < X16, "Absent Data", "Present")) -> Not Required | M16: spotify_cell_0s | N16: Entertainment | O16: =MAX(0, P16-Z16) -> 0 | P16: 0 | Q16: {=IFERROR(OFFSET(INDIRECT("Power."&M16&"!A1"),MATCH("Total Power (W)",INDIRECT("Power."&M16&"!A:A"),0)-1,MATCH("Std Dev",INDIRECT("Power."&M16&"!1:1"),0)-1),"")} | X16: =COUNTIFS(Classic_Scenarios_Measured[Scenario Weight], ">1%", Classic_Scenarios_Measured[Scenario], HOBL!M16) -> 0 | Y16: =COUNTIFS(Classic_Scenarios_Measured[Scorecard (W)], ">.001", Classic_Scenarios_Measured[Scenario], HOBL!M16) -> 0 | Z16: =MAX(0, COUNTA(INDIRECT("Power."&M16&"!B1:BA1"))-2) -> 0
B17: Screen On - Totals | D17: =18*Classic_HoBL_Summary6[[#This Row],["System On"]] -> 5.4 | E17: 0.3 | F17: =SUM(F8:F16) -> 0 | G17: =SUM(G8:G16) -> #DIV/0! | H17: =SUM(H8:H16) -> #DIV/0! | L17: =IF(X17=0, "Not Required", IF(Y17 < X17, "Absent Data", "Present")) -> Not Required | M17: local_audio_0s | N17: Entertainment | O17: =MAX(0, P17-Z17) -> 0 | P17: 0 | Q17: {=IFERROR(OFFSET(INDIRECT("Power."&M17&"!A1"),MATCH("Total Power (W)",INDIRECT("Power."&M17&"!A:A"),0)-1,MATCH("Std Dev",INDIRECT("Power."&M17&"!1:1"),0)-1),"")} | X17: =COUNTIFS(Classic_Scenarios_Measured[Scenario Weight], ">1%", Classic_Scenarios_Measured[Scenario], HOBL!M17) -> 0 | Y17: =COUNTIFS(Classic_Scenarios_Measured[Scorecard (W)], ">.001", Classic_Scenarios_Measured[Scenario], HOBL!M17) -> 0 | Z17: =MAX(0, COUNTA(INDIRECT("Power."&M17&"!B1:BA1"))-2) -> 0
B18: Totals | D18: =SUM(D7,D17) -> 18 | E18: =SUM(E7,E17) -> 1 | F18: =SUM(F7,F17) -> 0 | G18: =G7+G17 -> #DIV/0! | H18: =H7+H17 -> #DIV/0! | L18: =IF(X18=0, "Not Required", IF(Y18 < X18, "Absent Data", "Present")) -> Absent Data | M18: youtube_1s | N18: Entertainment | O18: =MAX(0, P18-Z18) -> 3 | P18: 3 | Q18: {=IFERROR(OFFSET(INDIRECT("Power."&M18&"!A1"),MATCH("Total Power (W)",INDIRECT("Power."&M18&"!A:A"),0)-1,MATCH("Std Dev",INDIRECT("Power."&M18&"!1:1"),0)-1),"")} | X18: =COUNTIFS(Classic_Scenarios_Measured[Scenario Weight], ">1%", Classic_Scenarios_Measured[Scenario], HOBL!M18) -> 1 | Y18: =COUNTIFS(Classic_Scenarios_Measured[Scorecard (W)], ">.001", Classic_Scenarios_Measured[Scenario], HOBL!M18) -> 0 | Z18: =MAX(0, COUNTA(INDIRECT("Power."&M18&"!B1:BA1"))-2) -> 0
C19: Battery Minimum Charge Capacity (Wh) | G19: 13.26 | L19: =IF(X19=0, "Not Required", IF(Y19 < X19, "Absent Data", "Present")) -> Not Required | M19: youtube_cell_1s | N19: Entertainment | O19: =MAX(0, P19-Z19) -> 0 | P19: 0 | Q19: {=IFERROR(OFFSET(INDIRECT("Power."&M19&"!A1"),MATCH("Total Power (W)",INDIRECT("Power."&M19&"!A:A"),0)-1,MATCH("Std Dev",INDIRECT("Power."&M19&"!1:1"),0)-1),"")} | X19: =COUNTIFS(Classic_Scenarios_Measured[Scenario Weight], ">1%", Classic_Scenarios_Measured[Scenario], HOBL!M19) -> 0 | Y19: =COUNTIFS(Classic_Scenarios_Measured[Scorecard (W)], ">.001", Classic_Scenarios_Measured[Scenario], HOBL!M19) -> 0 | Z19: =MAX(0, COUNTA(INDIRECT("Power."&M19&"!B1:BA1"))-2) -> 0
C20: Battery Typical Charge Capacity (Wh) | G20: 13.7 | L20: =IF(X20=0, "Not Required", IF(Y20 < X20, "Absent Data", "Present")) -> Not Required | M20: video_capture_w_2s | N20: Entertainment | O20: =MAX(0, P20-Z20) -> 0 | P20: 0 | Q20: {=IFERROR(OFFSET(INDIRECT("Power."&M20&"!A1"),MATCH("Total Power (W)",INDIRECT("Power."&M20&"!A:A"),0)-1,MATCH("Std Dev",INDIRECT("Power."&M20&"!1:1"),0)-1),"")} | X20: =COUNTIFS(Classic_Scenarios_Measured[Scenario Weight], ">1%", Classic_Scenarios_Measured[Scenario], HOBL!M20) -> 0 | Y20: =COUNTIFS(Classic_Scenarios_Measured[Scorecard (W)], ">.001", Classic_Scenarios_Measured[Scenario], HOBL!M20) -> 0 | Z20: =MAX(0, COUNTA(INDIRECT("Power."&M20&"!B1:BA1"))-2) -> 0
C21: Battery Protection Cuts (Wh) | G21: =Variable_Battery_FCC*H21 -> 0 | H21: 0 | L21: =IF(X21=0, "Not Required", IF(Y21 < X21, "Absent Data", "Present")) -> Not Required | M21: video_capture_f_2s | N21: Entertainment | O21: =MAX(0, P21-Z21) -> 0 | P21: 0 | Q21: {=IFERROR(OFFSET(INDIRECT("Power."&M21&"!A1"),MATCH("Total Power (W)",INDIRECT("Power."&M21&"!A:A"),0)-1,MATCH("Std Dev",INDIRECT("Power."&M21&"!1:1"),0)-1),"")} | X21: =COUNTIFS(Classic_Scenarios_Measured[Scenario Weight], ">1%", Classic_Scenarios_Measured[Scenario], HOBL!M21) -> 0 | Y21: =COUNTIFS(Classic_Scenarios_Measured[Scorecard (W)], ">.001", Classic_Scenarios_Measured[Scenario], HOBL!M21) -> 0 | Z21: =MAX(0, COUNTA(INDIRECT("Power."&M21&"!B1:BA1"))-2) -> 0
C22: OS shutdown Reserve (Wh) | G22: =Variable_Battery_FCC*H22 -> 0.137 | H22: 0.01 | L22: =IF(X22=0, "Not Required", IF(Y22 < X22, "Absent Data", "Present")) -> Not Required | M22: photo_pre_2s | N22: Entertainment | O22: =MAX(0, P22-Z22) -> 0 | P22: 0 | Q22: {=IFERROR(OFFSET(INDIRECT("Power."&M22&"!A1"),MATCH("Total Power (W)",INDIRECT("Power."&M22&"!A:A"),0)-1,MATCH("Std Dev",INDIRECT("Power."&M22&"!1:1"),0)-1),"")} | X22: =COUNTIFS(Classic_Scenarios_Measured[Scenario Weight], ">1%", Classic_Scenarios_Measured[Scenario], HOBL!M22) -> 0 | Y22: =COUNTIFS(Classic_Scenarios_Measured[Scorecard (W)], ">.001", Classic_Scenarios_Measured[Scenario], HOBL!M22) -> 0 | Z22: =MAX(0, COUNTA(INDIRECT("Power."&M22&"!B1:BA1"))-2) -> 0
C23: Total Available Battery Capacity (Wh) | G23: =Variable_Battery_FCC-SUM(G21:G22) -> 13.563 | L23: =IF(X23=0, "Not Required", IF(Y23 < X23, "Absent Data", "Present")) -> Absent Data | M23: teams_video_1s | N23: Communication | O23: =MAX(0, P23-Z23) -> 3 | P23: 3 | Q23: {=IFERROR(OFFSET(INDIRECT("Power."&M23&"!A1"),MATCH("Total Power (W)",INDIRECT("Power."&M23&"!A:A"),0)-1,MATCH("Std Dev",INDIRECT("Power."&M23&"!1:1"),0)-1),"")} | X23: =COUNTIFS(Classic_Scenarios_Measured[Scenario Weight], ">1%", Classic_Scenarios_Measured[Scenario], HOBL!M23) -> 1 | Y23: =COUNTIFS(Classic_Scenarios_Measured[Scorecard (W)], ">.001", Classic_Scenarios_Measured[Scenario], HOBL!M23) -> 0 | Z23: =MAX(0, COUNTA(INDIRECT("Power."&M23&"!B1:BA1"))-2) -> 0
C24: Standby Budget (Wh) | G24: =H7 -> #DIV/0! | L24: =IF(X24=0, "Not Required", IF(Y24 < X24, "Absent Data", "Present")) -> Absent Data | M24: minecraft_1s | N24: Gaming | O24: =MAX(0, P24-Z24) -> 3 | P24: 3 | Q24: {=IFERROR(OFFSET(INDIRECT("Power."&M24&"!A1"),MATCH("Total Power (W)",INDIRECT("Power."&M24&"!A:A"),0)-1,MATCH("Std Dev",INDIRECT("Power."&M24&"!1:1"),0)-1),"")} | X24: =COUNTIFS(Classic_Scenarios_Measured[Scenario Weight], ">1%", Classic_Scenarios_Measured[Scenario], HOBL!M24) -> 1 | Y24: =COUNTIFS(Classic_Scenarios_Measured[Scorecard (W)], ">.001", Classic_Scenarios_Measured[Scenario], HOBL!M24) -> 0 | Z24: =MAX(0, COUNTA(INDIRECT("Power."&M24&"!B1:BA1"))-2) -> 0
L25: =IF(X25=0, "Not Required", IF(Y25 < X25, "Absent Data", "Present")) -> Absent Data | M25: abl_prod_2s | N25: Productivity | O25: =MAX(0, P25-Z25) -> 3 | P25: 3 | Q25: {=IFERROR(OFFSET(INDIRECT("Power."&M25&"!A1"),MATCH("Total Power (W)",INDIRECT("Power."&M25&"!A:A"),0)-1,MATCH("Std Dev",INDIRECT("Power."&M25&"!1:1"),0)-1),"")} | X25: =COUNTIFS(Classic_Scenarios_Measured[Scenario Weight], ">1%", Classic_Scenarios_Measured[Scenario], HOBL!M25) -> 1 | Y25: =COUNTIFS(Classic_Scenarios_Measured[Scorecard (W)], ">.001", Classic_Scenarios_Measured[Scenario], HOBL!M25) -> 0 | Z25: =MAX(0, COUNTA(INDIRECT("Power."&M25&"!B1:BA1"))-2) -> 0
C26: Available Active Battery Capacity (Wh) | G26: =G23-SUM(G24:G24) -> #DIV/0! | L26: =IF(X26=0, "Not Required", IF(Y26 < X26, "Absent Data", "Present")) -> Absent Data | M26: voice_0s | N26: Smartphone | O26: =MAX(0, P26-Z26) -> 3 | P26: 3 | Q26: {=IFERROR(OFFSET(INDIRECT("Power."&M26&"!A1"),MATCH("Total Power (W)",INDIRECT("Power."&M26&"!A:A"),0)-1,MATCH("Std Dev",INDIRECT("Power."&M26&"!1:1"),0)-1),"")} | X26: =COUNTIFS(Classic_Scenarios_Measured[Scenario Weight], ">1%", Classic_Scenarios_Measured[Scenario], HOBL!M26) -> 1 | Y26: =COUNTIFS(Classic_Scenarios_Measured[Scorecard (W)], ">.001", Classic_Scenarios_Measured[Scenario], HOBL!M26) -> 0 | Z26: =MAX(0, COUNTA(INDIRECT("Power."&M26&"!B1:BA1"))-2) -> 0
C27: Screen On burnrate (W) | G27: =F17/E17 -> 0 | L27: =IF(X27=0, "Not Required", IF(Y27 < X27, "Absent Data", "Present")) -> Absent Data | M27: sms_1s | N27: Smartphone | O27: =MAX(0, P27-Z27) -> 3 | P27: 3 | Q27: {=IFERROR(OFFSET(INDIRECT("Power."&M27&"!A1"),MATCH("Total Power (W)",INDIRECT("Power."&M27&"!A:A"),0)-1,MATCH("Std Dev",INDIRECT("Power."&M27&"!1:1"),0)-1),"")} | X27: =COUNTIFS(Classic_Scenarios_Measured[Scenario Weight], ">1%", Classic_Scenarios_Measured[Scenario], HOBL!M27) -> 1 | Y27: =COUNTIFS(Classic_Scenarios_Measured[Scorecard (W)], ">.001", Classic_Scenarios_Measured[Scenario], HOBL!M27) -> 0 | Z27: =MAX(0, COUNTA(INDIRECT("Power."&M27&"!B1:BA1"))-2) -> 0
C28: Screen Off burnrate (W) | G28: =F7/E7 -> 0 | L28: =IF(X28=0, "Not Required", IF(Y28 < X28, "Absent Data", "Present")) -> Absent Data | M28: maps_1s | N28: Smartphone | O28: =MAX(0, P28-Z28) -> 3 | P28: 3 | Q28: {=IFERROR(OFFSET(INDIRECT("Power."&M28&"!A1"),MATCH("Total Power (W)",INDIRECT("Power."&M28&"!A:A"),0)-1,MATCH("Std Dev",INDIRECT("Power."&M28&"!1:1"),0)-1),"")} | X28: =COUNTIFS(Classic_Scenarios_Measured[Scenario Weight], ">1%", Classic_Scenarios_Measured[Scenario], HOBL!M28) -> 1 | Y28: =COUNTIFS(Classic_Scenarios_Measured[Scorecard (W)], ">.001", Classic_Scenarios_Measured[Scenario], HOBL!M28) -> 0 | Z28: =MAX(0, COUNTA(INDIRECT("Power."&M28&"!B1:BA1"))-2) -> 0
C29: HOBL Active On (h) | G29: =IF(Score_Prediction_HoBL<>"-NA-", Variable_Battery_Active/G27, "-NA-") -> -NA- | L29: =IF(X29=0, "Not Required", IF(Y29 < X29, "Absent Data", "Present")) -> Absent Data | M29: os_nav_2s | N29: System | O29: =MAX(0, P29-Z29) -> 3 | P29: 3 | Q29: {=IFERROR(OFFSET(INDIRECT("Power."&M29&"!A1"),MATCH("Total Power (W)",INDIRECT("Power."&M29&"!A:A"),0)-1,MATCH("Std Dev",INDIRECT("Power."&M29&"!1:1"),0)-1),"")} | X29: =COUNTIFS(Classic_Scenarios_Measured[Scenario Weight], ">1%", Classic_Scenarios_Measured[Scenario], HOBL!M29) -> 1 | Y29: =COUNTIFS(Classic_Scenarios_Measured[Scorecard (W)], ">.001", Classic_Scenarios_Measured[Scenario], HOBL!M29) -> 0 | Z29: =MAX(0, COUNTA(INDIRECT("Power."&M29&"!B1:BA1"))-2) -> 0
C30: HOBL Screen Off (h) | G30: =IF(Score_Prediction_HoBL<>"-NA-",Variable_Battery_Standby/G28, "-NA-") -> -NA- | L30: =IF(X30=0, "Not Required", IF(Y30 < X30, "Absent Data", "Present")) -> Absent Data | M30: sspnd_app_wifi_0s | N30: Standby | O30: =MAX(0, P30-Z30) -> 5 | P30: 5 | Q30: {=IFERROR(OFFSET(INDIRECT("Power."&M30&"!A1"),MATCH("Total Power (W)",INDIRECT("Power."&M30&"!A:A"),0)-1,MATCH("Std Dev",INDIRECT("Power."&M30&"!1:1"),0)-1),"")} | X30: =COUNTIFS(Classic_Scenarios_Measured[Scenario Weight], ">1%", Classic_Scenarios_Measured[Scenario], HOBL!M30) -> 1 | Y30: =COUNTIFS(Classic_Scenarios_Measured[Scorecard (W)], ">.001", Classic_Scenarios_Measured[Scenario], HOBL!M30) -> 0 | Z30: =MAX(0, COUNTA(INDIRECT("Power."&M30&"!B1:BA1"))-2) -> 0
C31: Estimated TenApps Carrier Standby (h) | G31: {=IF(INDEX(L7:L39, MATCH("sspnd_app_cell_0s", M7:M39, 0), 0)<>"Absent Data", Variable_Battery_Minimum/VLOOKUP("sspnd_app_cell_0s",Classic_Scenarios_Measured[[Scenario]:[Posture Weighted Power & Adders (W)]], 4, FALSE), "-NA-")} -> -NA- | L31: =IF(X31=0, "Not Required", IF(Y31 < X31, "Absent Data", "Present")) -> Not Required | M31: sspnd_idl_wifi_0s | N31: Standby | O31: =MAX(0, P31-Z31) -> 0 | P31: 0 | Q31: {=IFERROR(OFFSET(INDIRECT("Power."&M31&"!A1"),MATCH("Total Power (W)",INDIRECT("Power."&M31&"!A:A"),0)-1,MATCH("Std Dev",INDIRECT("Power."&M31&"!1:1"),0)-1),"")} | X31: =COUNTIFS(Classic_Scenarios_Measured[Scenario Weight], ">1%", Classic_Scenarios_Measured[Scenario], HOBL!M31) -> 0 | Y31: =COUNTIFS(Classic_Scenarios_Measured[Scorecard (W)], ">.001", Classic_Scenarios_Measured[Scenario], HOBL!M31) -> 0 | Z31: =MAX(0, COUNTA(INDIRECT("Power."&M31&"!B1:BA1"))-2) -> 0
L32: =IF(X32=0, "Not Required", IF(Y32 < X32, "Absent Data", "Present")) -> Absent Data | M32: sspnd_app_cell_0s | N32: Standby | O32: =MAX(0, P32-Z32) -> 5 | P32: 5 | Q32: {=IFERROR(OFFSET(INDIRECT("Power."&M32&"!A1"),MATCH("Total Power (W)",INDIRECT("Power."&M32&"!A:A"),0)-1,MATCH("Std Dev",INDIRECT("Power."&M32&"!1:1"),0)-1),"")} | X32: =COUNTIFS(Classic_Scenarios_Measured[Scenario Weight], ">1%", Classic_Scenarios_Measured[Scenario], HOBL!M32) -> 1 | Y32: =COUNTIFS(Classic_Scenarios_Measured[Scorecard (W)], ">.001", Classic_Scenarios_Measured[Scenario], HOBL!M32) -> 0 | Z32: =MAX(0, COUNTA(INDIRECT("Power."&M32&"!B1:BA1"))-2) -> 0
C33: Talk Time (h) | G33: 0 | L33: =IF(X33=0, "Not Required", IF(Y33 < X33, "Absent Data", "Present")) -> Not Required | M33: sspnd_idl_cell_0s | N33: Standby | O33: =MAX(0, P33-Z33) -> 0 | P33: 0 | Q33: {=IFERROR(OFFSET(INDIRECT("Power."&M33&"!A1"),MATCH("Total Power (W)",INDIRECT("Power."&M33&"!A:A"),0)-1,MATCH("Std Dev",INDIRECT("Power."&M33&"!1:1"),0)-1),"")} | X33: =COUNTIFS(Classic_Scenarios_Measured[Scenario Weight], ">1%", Classic_Scenarios_Measured[Scenario], HOBL!M33) -> 0 | Y33: =COUNTIFS(Classic_Scenarios_Measured[Scorecard (W)], ">.001", Classic_Scenarios_Measured[Scenario], HOBL!M33) -> 0 | Z33: =MAX(0, COUNTA(INDIRECT("Power."&M33&"!B1:BA1"))-2) -> 0
C34: HOBL Lab Prediction (h) | G34: =IF(COUNTIF($L$7:$L$39, "Absent Data")>0, "-NA-", Variable_Battery_Available/F18) -> -NA- | L34: =IF(X34=0, "Not Required", IF(Y34 < X34, "Absent Data", "Present")) -> Not Required | M34: sspnd_idl_apm_0s | N34: Standby | O34: =MAX(0, P34-Z34) -> 5 | P34: 5 | Q34: {=IFERROR(OFFSET(INDIRECT("Power."&M34&"!A1"),MATCH("Total Power (W)",INDIRECT("Power."&M34&"!A:A"),0)-1,MATCH("Std Dev",INDIRECT("Power."&M34&"!1:1"),0)-1),"")} | X34: =COUNTIFS(Classic_Scenarios_Measured[Scenario Weight], ">1%", Classic_Scenarios_Measured[Scenario], HOBL!M34) -> 0 | Y34: =COUNTIFS(Classic_Scenarios_Measured[Scorecard (W)], ">.001", Classic_Scenarios_Measured[Scenario], HOBL!M34) -> 0 | Z34: =MAX(0, COUNTA(INDIRECT("Power."&M34&"!B1:BA1"))-2) -> 0
C35: ABL Lab DAQ Measurement (h) | G35: =IF(L39<>"Absent Data", Variable_Battery_Available/(VLOOKUP("abl_act_xs",Classic_Scenarios_Measured[[Scenario]:[Posture Weighted Power & Adders (W)]], 4, FALSE)*30%+G28*70%), "-NA-") -> -NA- | L35: =IF(X35=0, "Not Required", IF(Y35 < X35, "Absent Data", "Present")) -> Not Required | M35: idle_home_2s | N35: Idle | O35: =MAX(0, P35-Z35) -> 0 | P35: 0 | Q35: {=IFERROR(OFFSET(INDIRECT("Power."&M35&"!A1"),MATCH("Total Power (W)",INDIRECT("Power."&M35&"!A:A"),0)-1,MATCH("Std Dev",INDIRECT("Power."&M35&"!1:1"),0)-1),"")} | X35: =COUNTIFS(Classic_Scenarios_Measured[Scenario Weight], ">1%", Classic_Scenarios_Measured[Scenario], HOBL!M35) -> 0 | Y35: =COUNTIFS(Classic_Scenarios_Measured[Scorecard (W)], ">.001", Classic_Scenarios_Measured[Scenario], HOBL!M35) -> 0 | Z35: =MAX(0, COUNTA(INDIRECT("Power."&M35&"!B1:BA1"))-2) -> 0
L36: =IF(X36=0, "Not Required", IF(Y36 < X36, "Absent Data", "Present")) -> Not Required | M36: idle_home_cell_2s | N36: Idle | O36: =MAX(0, P36-Z36) -> 3 | P36: 3 | Q36: {=IFERROR(OFFSET(INDIRECT("Power."&M36&"!A1"),MATCH("Total Power (W)",INDIRECT("Power."&M36&"!A:A"),0)-1,MATCH("Std Dev",INDIRECT("Power."&M36&"!1:1"),0)-1),"")} | X36: =COUNTIFS(Classic_Scenarios_Measured[Scenario Weight], ">1%", Classic_Scenarios_Measured[Scenario], HOBL!M36) -> 0 | Y36: =COUNTIFS(Classic_Scenarios_Measured[Scorecard (W)], ">.001", Classic_Scenarios_Measured[Scenario], HOBL!M36) -> 0 | Z36: =MAX(0, COUNTA(INDIRECT("Power."&M36&"!B1:BA1"))-2) -> 0
C37: ABL Active On Lab DAQ Measurement (h) | G37: =IF(L39<>"Absent Data", Variable_Battery_Available/VLOOKUP("abl_act_xs",Classic_Scenarios_Measured[[Scenario]:[Posture Weighted Power & Adders (W)]], 4, FALSE),"-NA-") -> -NA- | L37: =IF(X37=0, "Not Required", IF(Y37 < X37, "Absent Data", "Present")) -> Not Required | M37: idle_home_apm_2s | N37: Idle | O37: =MAX(0, P37-Z37) -> 3 | P37: 3 | Q37: {=IFERROR(OFFSET(INDIRECT("Power."&M37&"!A1"),MATCH("Total Power (W)",INDIRECT("Power."&M37&"!A:A"),0)-1,MATCH("Std Dev",INDIRECT("Power."&M37&"!1:1"),0)-1),"")} | X37: =COUNTIFS(Classic_Scenarios_Measured[Scenario Weight], ">1%", Classic_Scenarios_Measured[Scenario], HOBL!M37) -> 0 | Y37: =COUNTIFS(Classic_Scenarios_Measured[Scorecard (W)], ">.001", Classic_Scenarios_Measured[Scenario], HOBL!M37) -> 0 | Z37: =MAX(0, COUNTA(INDIRECT("Power."&M37&"!B1:BA1"))-2) -> 0
C38: LAP (h) | G38: =IFERROR(Variable_Battery_Available/VLOOKUP("local_audio_0s",Classic_Scenarios_Measured[[Scenario]:[Posture Weighted Power & Adders (W)]], 4, FALSE), "-NA-") -> -NA- | L38: =IF(X38=0, "Not Required", IF(Y38 < X38, "Absent Data", "Present")) -> Not Required | M38: idle_home_1s | N38: Idle | O38: =MAX(0, P38-Z38) -> 0 | P38: 0 | Q38: {=IFERROR(OFFSET(INDIRECT("Power."&M38&"!A1"),MATCH("Total Power (W)",INDIRECT("Power."&M38&"!A:A"),0)-1,MATCH("Std Dev",INDIRECT("Power."&M38&"!1:1"),0)-1),"")} | X38: =COUNTIFS(Classic_Scenarios_Measured[Scenario Weight], ">1%", Classic_Scenarios_Measured[Scenario], HOBL!M38) -> 0 | Y38: =COUNTIFS(Classic_Scenarios_Measured[Scorecard (W)], ">.001", Classic_Scenarios_Measured[Scenario], HOBL!M38) -> 0 | Z38: =MAX(0, COUNTA(INDIRECT("Power."&M38&"!B1:BA1"))-2) -> 0
C39: LVP (h) | G39: =IFERROR(Variable_Battery_Available/VLOOKUP("local_video_1s",Classic_Scenarios_Measured[[Scenario]:[Posture Weighted Power & Adders (W)]], 4, FALSE), "-NA-") -> -NA- | L39: =IF(X39=0, "Not Required", IF(Y39 < X39, "Absent Data", "Present")) -> Absent Data | M39: abl_act_xs | N39: Mixed | O39: =MAX(0, P39-Z39) -> 5 | P39: 5 | Q39: {=IFERROR(OFFSET(INDIRECT("Power."&M39&"!A1"),MATCH("Total Power (W)",INDIRECT("Power."&M39&"!A:A"),0)-1,MATCH("Std Dev",INDIRECT("Power."&M39&"!1:1"),0)-1),"")} | X39: =COUNTIFS(Classic_Scenarios_Measured[Scenario Weight], ">1%", Classic_Scenarios_Measured[Scenario], HOBL!M39) -> 1 | Y39: =COUNTIFS(Classic_Scenarios_Measured[Scorecard (W)], ">.001", Classic_Scenarios_Measured[Scenario], HOBL!M39) -> 0 | Z39: =MAX(0, COUNTA(INDIRECT("Power."&M39&"!B1:BA1"))-2) -> 0
I52: Nickname | J52: Study | K52: ABL Active On | L52: ABL Active On Target | M52: HOBL | N52: HOBL Target | O52: ABL Telemetry | P52: Standby Telemetry
I53: =SUBSTITUTE(SUBSTITUTE(SUBSTITUTE(J53, "LKG_20", ""), "_CUS", ""), "_test_perf", "")
...

Sheet Scenarios
A2: Input | B2: Calculated | C2: Calculated
A3: Categories | B3: Category Weight | C3: Usage Time (hrs) | D3: Category Power (W) | E3: HoBL Power (W)
A4: Web | B4: 0.075 | C4: =18*Classic_Categories_Measured[[#This Row],[Category Weight]] -> 1.35 | D4: {=SUMPRODUCT((Classic_Scenarios_Measured[Scenario Weight]*Classic_Scenarios_Measured[Posture Weighted Power & Adders (W)])*(Classic_Scenarios_Measured[Category]=Classic_Categories_Measured[[#This Row],[Categories]]))} -> 0 | E4: =Classic_Categories_Measured[[#This Row],[Category Power (W)]]*Classic_Categories_Measured[[#This Row],[Category Weight]] -> 0
A5: Productivity | B5: 0.045 | C5: =18*Classic_Categories_Measured[[#This Row],[Category Weight]] -> 0.81 | D5: {=SUMPRODUCT((Classic_Scenarios_Measured[Scenario Weight]*Classic_Scenarios_Measured[Posture Weighted Power & Adders (W)])*(Classic_Scenarios_Measured[Category]=Classic_Categories_Measured[[#This Row],[Categories]]))} -> 0 | E5: =Classic_Categories_Measured[[#This Row],[Category Power (W)]]*Classic_Categories_Measured[[#This Row],[Category Weight]] -> 0
A6: Communication | B6: 0.03 | C6: =18*Classic_Categories_Measured[[#This Row],[Category Weight]] -> 0.54 | D6: {=SUMPRODUCT((Classic_Scenarios_Measured[Scenario Weight]*Classic_Scenarios_Measured[Posture Weighted Power & Adders (W)])*(Classic_Scenarios_Measured[Category]=Classic_Categories_Measured[[#This Row],[Categories]]))} -> 0 | E6: =Classic_Categories_Measured[[#This Row],[Category Power (W)]]*Classic_Categories_Measured[[#This Row],[Category Weight]] -> 0
A7: Gaming | B7: 0.03 | C7: =18*Classic_Categories_Measured[[#This Row],[Category Weight]] -> 0.54 | D7: {=SUMPRODUCT((Classic_Scenarios_Measured[Scenario Weight]*Classic_Scenarios_Measured[Posture Weighted Power & Adders (W)])*(Classic_Scenarios_Measured[Category]=Classic_Categories_Measured[[#This Row],[Categories]]))} -> 0 | E7: =Classic_Categories_Measured[[#This Row],[Category Power (W)]]*Classic_Categories_Measured[[#This Row],[Category Weight]] -> 0
A8: Entertainment | B8: 0.03 | C8: =18*Classic_Categories_Measured[[#This Row],[Category Weight]] -> 0.54 | D8: {=SUMPRODUCT((Classic_Scenarios_Measured[Scenario Weight]*Classic_Scenarios_Measured[Posture Weighted Power & Adders (W)])*(Classic_Scenarios_Measured[Category]=Classic_Categories_Measured[[#This Row],[Categories]]))} -> 0 | E8: =Classic_Categories_Measured[[#This Row],[Category Power (W)]]*Classic_Categories_Measured[[#This Row],[Category Weight]] -> 0
A9: Social | B9: 0.06 | C9: =18*Classic_Categories_Measured[[#This Row],[Category Weight]] -> 1.08 | D9: {=SUMPRODUCT((Classic_Scenarios_Measured[Scenario Weight]*Classic_Scenarios_Measured[Posture Weighted Power & Adders (W)])*(Classic_Scenarios_Measured[Category]=Classic_Categories_Measured[[#This Row],[Categories]]))} -> 0 | E9: =Classic_Categories_Measured[[#This Row],[Category Power (W)]]*Classic_Categories_Measured[[#This Row],[Category Weight]] -> 0
A10: Smartphone | B10: 0.015 | C10: =18*Classic_Categories_Measured[[#This Row],[Category Weight]] -> 0.27 | D10: {=SUMPRODUCT((Classic_Scenarios_Measured[Scenario Weight]*Classic_Scenarios_Measured[Posture Weighted Power & Adders (W)])*(Classic_Scenarios_Measured[Category]=Classic_Categories_Measured[[#This Row],[Categories]]))} -> 0 | E10: =Classic_Categories_Measured[[#This Row],[Category Power (W)]]*Classic_Categories_Measured[[#This Row],[Category Weight]] -> 0
A11: System | B11: 0.015 | C11: =18*Classic_Categories_Measured[[#This Row],[Category Weight]] -> 0.27 | D11: {=SUMPRODUCT((Classic_Scenarios_Measured[Scenario Weight]*Classic_Scenarios_Measured[Posture Weighted Power & Adders (W)])*(Classic_Scenarios_Measured[Category]=Classic_Categories_Measured[[#This Row],[Categories]]))} -> 0 | E11: =Classic_Categories_Measured[[#This Row],[Category Power (W)]]*Classic_Categories_Measured[[#This Row],[Category Weight]] -> 0
A12: Idle | B12: 0 | C12: =18*Classic_Categories_Measured[[#This Row],[Category Weight]] -> 0 | D12: {=SUMPRODUCT((Classic_Scenarios_Measured[Scenario Weight]*Classic_Scenarios_Measured[Posture Weighted Power & Adders (W)])*(Classic_Scenarios_Measured[Category]=Classic_Categories_Measured[[#This Row],[Categories]]))} -> 0 | E12: =Classic_Categories_Measured[[#This Row],[Category Power (W)]]*Classic_Categories_Measured[[#This Row],[Category Weight]] -> 0
A13: Standby | B13: 0.7 | C13: =18*Classic_Categories_Measured[[#This Row],[Category Weight]] -> 12.6 | D13: {=SUMPRODUCT((Classic_Scenarios_Measured[Scenario Weight]*Classic_Scenarios_Measured[Posture Weighted Power & Adders (W)])*(Classic_Scenarios_Measured[Category]=Classic_Categories_Measured[[#This Row],[Categories]]))} -> 0 | E13: =Classic_Categories_Measured[[#This Row],[Category Power (W)]]*Classic_Categories_Measured[[#This Row],[Category Weight]] -> 0
A14: Mixed | B14: 0 | C14: =18*Classic_Categories_Measured[[#This Row],[Category Weight]] -> 0 | D14: {=SUMPRODUCT((Classic_Scenarios_Measured[Scenario Weight]*Classic_Scenarios_Measured[Posture Weighted Power & Adders (W)])*(Classic_Scenarios_Measured[Category]=Classic_Categories_Measured[[#This Row],[Categories]]))} -> 0 | E14: =Classic_Categories_Measured[[#This Row],[Category Power (W)]]*Classic_Categories_Measured[[#This Row],[Category Weight]] -> 0
A15: Shutdown | B15: 0 | C15: =18*Classic_Categories_Measured[[#This Row],[Category Weight]] -> 0 | D15: {=SUMPRODUCT((Classic_Scenarios_Measured[Scenario Weight]*Classic_Scenarios_Measured[Posture Weighted Power & Adders (W)])*(Classic_Scenarios_Measured[Category]=Classic_Categories_Measured[[#This Row],[Categories]]))} -> 0 | E15: =Classic_Categories_Measured[[#This Row],[Category Power (W)]]*Classic_Categories_Measured[[#This Row],[Category Weight]] -> 0
A16: Undefined | B16: 0 | C16: =18*Classic_Categories_Measured[[#This Row],[Category Weight]] -> 0 | D16: {=SUMPRODUCT((Classic_Scenarios_Measured[Scenario Weight]*Classic_Scenarios_Measured[Posture Weighted Power & Adders (W)])*(Classic_Scenarios_Measured[Category]=Classic_Categories_Measured[[#This Row],[Categories]]))} -> 0 | E16: =Classic_Categories_Measured[[#This Row],[Category Power (W)]]*Classic_Categories_Measured[[#This Row],[Category Weight]] -> 0
C17: =SUBTOTAL(109,Classic_Categories_Measured[Usage Time (hrs)]) -> 18 | E17: =SUBTOTAL(109,Classic_Categories_Measured[HoBL Power (W)]) -> 0
A20: Calculated | B20: Calculated | C20: Calculated | D20: Input | E20: Calculated | F20: Calculated | G20: Calculated | H20: Calculated | I20: Input | J20: Calculated | K20: Calculated
A21: Category Weight | B21: Category' | C21: Category | D21: Scenario | E21: Scenario Duration (hrs) | F21: Scenario Weight | G21: Posture Weighted Power & Adders (W) | H21: Adders (W) | I21: Manual Adder (W) | J21: Touch Adder (W) | K21: Scorecard (W)
A22: =IF(B22<>"",SUMIF(Classic_Scenarios_Measured[Category],Classic_Scenarios_Measured[[#This Row],[Category]],Classic_Scenarios_Measured[Scenario Weight]),"") -> 1 | B22: =IF(C22<>C21,C22,"") -> Social | C22: Social | D22: facebook_1s | E22: =_xlfn.IFNA(VLOOKUP(Classic_Scenarios_Measured[[#This Row],[Category]],Classic_Categories_Measured[],2,FALSE),"")*Classic_Scenarios_Measured[[#This Row],[Scenario Weight]] -> 0.03 | F22: 0.5 | G22: =SUM(Classic_Scenarios_Measured[[#This Row],[Adders (W)]], Classic_Scenarios_Measured[[#This Row],[Scorecard (W)]]) -> 0 | H22: =IF(Classic_Scenarios_Measured[[#This Row],[Scorecard (W)]]<>"", SUM(Classic_Scenarios_Measured[[#This Row],[Manual Adder (W)]:[Touch Adder (W)]]), "") | J22: 0.1785 | K22: =IF(OFFSET(Scorecard!$B$15, 0, MATCH(Classic_Scenarios_Measured[[#This Row],[Scenario]], Scorecard!$B$2:$BC$2,0))<>"", OFFSET(Scorecard!$B$15, 0, MATCH(Classic_Scenarios_Measured[[#This Row],[Scenario]], Scorecard!$B$2:$BC$2,0))/1000, "")
A23: =IF(B23<>"",SUMIF(Classic_Scenarios_Measured[Category],Classic_Scenarios_Measured[[#This Row],[Category]],Classic_Scenarios_Measured[Scenario Weight]),"") | B23: =IF(C23<>C22,C23,"") | C23: Social | D23: instagram_1s | E23: =_xlfn.IFNA(VLOOKUP(Classic_Scenarios_Measured[[#This Row],[Category]],Classic_Categories_Measured[],2,FALSE),"")*Classic_Scenarios_Measured[[#This Row],[Scenario Weight]] -> 0 | F23: 0 | G23: =SUM(Classic_Scenarios_Measured[[#This Row],[Adders (W)]], Classic_Scenarios_Measured[[#This Row],[Scorecard (W)]]) -> 0 | H23: =IF(Classic_Scenarios_Measured[[#This Row],[Scorecard (W)]]<>"", SUM(Classic_Scenarios_Measured[[#This Row],[Manual Adder (W)]:[Touch Adder (W)]]), "") | J23: 0.1785 | K23: =IF(OFFSET(Scorecard!$B$15, 0, MATCH(Classic_Scenarios_Measured[[#This Row],[Scenario]], Scorecard!$B$2:$BC$2,0))<>"", OFFSET(Scorecard!$B$15, 0, MATCH(Classic_Scenarios_Measured[[#This Row],[Scenario]], Scorecard!$B$2:$BC$2,0))/1000, "")
A24: =IF(B24<>"",SUMIF(Classic_Scenarios_Measured[Category],Classic_Scenarios_Measured[[#This Row],[Category]],Classic_Scenarios_Measured[Scenario Weight]),"") | B24: =IF(C24<>C23,C24,"") | C24: Social | D24: instagram_2s | E24: =_xlfn.IFNA(VLOOKUP(Classic_Scenarios_Measured[[#This Row],[Category]],Classic_Categories_Measured[],2,FALSE),"")*Classic_Scenarios_Measured[[#This Row],[Scenario Weight]] -> 0.03 | F24: 0.5 | G24: =SUM(Classic_Scenarios_Measured[[#This Row],[Adders (W)]], Classic_Scenarios_Measured[[#This Row],[Scorecard (W)]]) -> 0 | H24: =IF(Classic_Scenarios_Measured[[#This Row],[Scorecard (W)]]<>"", SUM(Classic_Scenarios_Measured[[#This Row],[Manual Adder (W)]:[Touch Adder (W)]]), "") | J24: 0.2814 | K24: =IF(OFFSET(Scorecard!$B$15, 0, MATCH(Classic_Scenarios_Measured[[#This Row],[Scenario]], Scorecard!$B$2:$BC$2,0))<>"", OFFSET(Scorecard!$B$15, 0, MATCH(Classic_Scenarios_Measured[[#This Row],[Scenario]], Scorecard!$B$2:$BC$2,0))/1000, "")
A25: =IF(B25<>"",SUMIF(Classic_Scenarios_Measured[Category],Classic_Scenarios_Measured[[#This Row],[Category]],Classic_Scenarios_Measured[Scenario Weight]),"") -> 1 | B25: =IF(C25<>C24,C25,"") -> Web | C25: Web | D25: edge_1s | E25: =_xlfn.IFNA(VLOOKUP(Classic_Scenarios_Measured[[#This Row],[Category]],Classic_Categories_Measured[],2,FALSE),"")*Classic_Scenarios_Measured[[#This Row],[Scenario Weight]] -> 0.01875 | F25: 0.25 | G25: =SUM(Classic_Scenarios_Measured[[#This Row],[Adders (W)]], Classic_Scenarios_Measured[[#This Row],[Scorecard (W)]]) -> 0 | H25: =IF(Classic_Scenarios_Measured[[#This Row],[Scorecard (W)]]<>"", SUM(Classic_Scenarios_Measured[[#This Row],[Manual Adder (W)]:[Touch Adder (W)]]), "") | J25: 0.1548 | K25: =IF(OFFSET(Scorecard!$B$15, 0, MATCH(Classic_Scenarios_Measured[[#This Row],[Scenario]], Scorecard!$B$2:$BC$2,0))<>"", OFFSET(Scorecard!$B$15, 0, MATCH(Classic_Scenarios_Measured[[#This Row],[Scenario]], Scorecard!$B$2:$BC$2,0))/1000, "")
A26: =IF(B26<>"",SUMIF(Classic_Scenarios_Measured[Category],Classic_Scenarios_Measured[[#This Row],[Category]],Classic_Scenarios_Measured[Scenario Weight]),"") | B26: =IF(C26<>C25,C26,"") | C26: Web | D26: edge_fb_2s | E26: =_xlfn.IFNA(VLOOKUP(Classic_Scenarios_Measured[[#This Row],[Category]],Classic_Categories_Measured[],2,FALSE),"")*Classic_Scenarios_Measured[[#This Row],[Scenario Weight]] -> 0.05625 | F26: 0.75 | G26: =SUM(Classic_Scenarios_Measured[[#This Row],[Adders (W)]], Classic_Scenarios_Measured[[#This Row],[Scorecard (W)]]) -> 0 | H26: =IF(Classic_Scenarios_Measured[[#This Row],[Scorecard (W)]]<>"", SUM(Classic_Scenarios_Measured[[#This Row],[Manual Adder (W)]:[Touch Adder (W)]]), "") | J26: 0.3165 | K26: =IF(OFFSET(Scorecard!$B$15, 0, MATCH(Classic_Scenarios_Measured[[#This Row],[Scenario]], Scorecard!$B$2:$BC$2,0))<>"", OFFSET(Scorecard!$B$15, 0, MATCH(Classic_Scenarios_Measured[[#This Row],[Scenario]], Scorecard!$B$2:$BC$2,0))/1000, "")
A27: =IF(B27<>"",SUMIF(Classic_Scenarios_Measured[Category],Classic_Scenarios_Measured[[#This Row],[Category]],Classic_Scenarios_Measured[Scenario Weight]),"") -> 1 | B27: =IF(C27<>C26,C27,"") -> Entertainment | C27: Entertainment | D27: local_video_1s | E27: =_xlfn.IFNA(VLOOKUP(Classic_Scenarios_Measured[[#This Row],[Category]],Classic_Categories_Measured[],2,FALSE),"")*Classic_Scenarios_Measured[[#This Row],[Scenario Weight]] -> 0 | F27: 0 | G27: =SUM(Classic_Scenarios_Measured[[#This Row],[Adders (W)]], Classic_Scenarios_Measured[[#This Row],[Scorecard (W)]]) -> 0 | H27: =IF(Classic_Scenarios_Measured[[#This Row],[Scorecard (W)]]<>"", SUM(Classic_Scenarios_Measured[[#This Row],[Manual Adder (W)]:[Touch Adder (W)]]), "") | J27: 0.0013 | K27: =IF(OFFSET(Scorecard!$B$15, 0, MATCH(Classic_Scenarios_Measured[[#This Row],[Scenario]], Scorecard!$B$2:$BC$2,0))<>"", OFFSET(Scorecard!$B$15, 0, MATCH(Classic_Scenarios_Measured[[#This Row],[Scenario]], Scorecard!$B$2:$BC$2,0))/1000, "")
A28: =IF(B28<>"",SUMIF(Classic_Scenarios_Measured[Category],Classic_Scenarios_Measured[[#This Row],[Category]],Classic_Scenarios_Measured[Scenario Weight]),"") | B28: =IF(C28<>C27,C28,"") | C28: Entertainment | D28: spotify_0s | E28: =_xlfn.IFNA(VLOOKUP(Classic_Scenarios_Measured[[#This Row],[Category]],Classic_Categories_Measured[],2,FALSE),"")*Classic_Scenarios_Measured[[#This Row],[Scenario Weight]] -> 0.006 | F28: 0.2 | G28: =SUM(Classic_Scenarios_Measured[[#This Row],[Adders (W)]], Classic_Scenarios_Measured[[#This Row],[Scorecard (W)]]) -> 0 | H28: =IF(Classic_Scenarios_Measured[[#This Row],[Scorecard (W)]]<>"", SUM(Classic_Scenarios_Measured[[#This Row],[Manual Adder (W)]:[Touch Adder (W)]]), "") | J28: 0.0013 | K28: =IF(OFFSET(Scorecard!$B$15, 0, MATCH(Classic_Scenarios_Measured[[#This Row],[Scenario]], Scorecard!$B$2:$BC$2,0))<>"", OFFSET(Scorecard!$B$15, 0, MATCH(Classic_Scenarios_Measured[[#This Row],[Scenario]], Scorecard!$B$2:$BC$2,0))/1000, "")
A29: =IF(B29<>"",SUMIF(Classic_Scenarios_Measured[Category],Classic_Scenarios_Measured[[#This Row],[Category]],Classic_Scenarios_Measured[Scenario Weight]),"") | B29: =IF(C29<>C28,C29,"") | C29: Entertainment | D29: local_audio_0s | E29: =_xlfn.IFNA(VLOOKUP(Classic_Scenarios_Measured[[#This Row],[Category]],Classic_Categories_Measured[],2,FALSE),"")*Classic_Scenarios_Measured[[#This Row],[Scenario Weight]] -> 0 | F29: 0 | G29: =SUM(Classic_Scenarios_Measured[[#This Row],[Adders (W)]], Classic_Scenarios_Measured[[#This Row],[Scorecard (W)]]) -> 0 | H29: =IF(Classic_Scenarios_Measured[[#This Row],[Scorecard (W)]]<>"", SUM(Classic_Scenarios_Measured[[#This Row],[Manual Adder (W)]:[Touch Adder (W)]]), "") | J29: 0.0013 | K29: =IF(OFFSET(Scorecard!$B$15, 0, MATCH(Classic_Scenarios_Measured[[#This Row],[Scenario]], Scorecard!$B$2:$BC$2,0))<>"", OFFSET(Scorecard!$B$15, 0, MATCH(Classic_Scenarios_Measured[[#This Row],[Scenario]], Scorecard!$B$2:$BC$2,0))/1000, "")
A30: =IF(B30<>"",SUMIF(Classic_Scenarios_Measured[Category],Classic_Scenarios_Measured[[#This Row],[Category]],Classic_Scenarios_Measured[Scenario Weight]),"") | B30: =IF(C30<>C29,C30,"") | C30: Entertainment | D30: youtube_1s | E30: =_xlfn.IFNA(VLOOKUP(Classic_Scenarios_Measured[[#This Row],[Category]],Classic_Categories_Measured[],2,FALSE),"")*Classic_Scenarios_Measured[[#This Row],[Scenario Weight]] -> 0.024 | F30: 0.8 | G30: =SUM(Classic_Scenarios_Measured[[#This Row],[Adders (W)]], Classic_Scenarios_Measured[[#This Row],[Scorecard (W)]]) -> 0 | H30: =IF(Classic_Scenarios_Measured[[#This Row],[Scorecard (W)]]<>"", SUM(Classic_Scenarios_Measured[[#This Row],[Manual Adder (W)]:[Touch Adder (W)]]), "") | J30: 0.0013 | K30: =IF(OFFSET(Scorecard!$B$15, 0, MATCH(Classic_Scenarios_Measured[[#This Row],[Scenario]], Scorecard!$B$2:$BC$2,0))<>"", OFFSET(Scorecard!$B$15, 0, MATCH(Classic_Scenarios_Measured[[#This Row],[Scenario]], Scorecard!$B$2:$BC$2,0))/1000, "")
A31: =IF(B31<>"",SUMIF(Classic_Scenarios_Measured[Category],Classic_Scenarios_Measured[[#This Row],[Category]],Classic_Scenarios_Measured[Scenario Weight]),"") | B31: =IF(C31<>C30,C31,"") | C31: Entertainment | D31: video_capture_w_2s | E31: =_xlfn.IFNA(VLOOKUP(Classic_Scenarios_Measured[[#This Row],[Category]],Classic_Categories_Measured[],2,FALSE),"")*Classic_Scenarios_Measured[[#This Row],[Scenario Weight]] -> 0 | F31: 0 | G31: =SUM(Classic_Scenarios_Measured[[#This Row],[Adders (W)]], Classic_Scenarios_Measured[[#This Row],[Scorecard (W)]]) -> 0 | H31: =IF(Classic_Scenarios_Measured[[#This Row],[Scorecard (W)]]<>"", SUM(Classic_Scenarios_Measured[[#This Row],[Manual Adder (W)]:[Touch Adder (W)]]), "") | J31: 0.0013 | K31: =IF(OFFSET(Scorecard!$B$15, 0, MATCH(Classic_Scenarios_Measured[[#This Row],[Scenario]], Scorecard!$B$2:$BC$2,0))<>"", OFFSET(Scorecard!$B$15, 0, MATCH(Classic_Scenarios_Measured[[#This Row],[Scenario]], Scorecard!$B$2:$BC$2,0))/1000, "")
A32: =IF(B32<>"",SUMIF(Classic_Scenarios_Measured[Category],Classic_Scenarios_Measured[[#This Row],[Category]],Classic_Scenarios_Measured[Scenario Weight]),"") | B32: =IF(C32<>C31,C32,"") | C32: Entertainment | D32: photo_pre_2s | E32: =_xlfn.IFNA(VLOOKUP(Classic_Scenarios_Measured[[#This Row],[Category]],Classic_Categories_Measured[],2,FALSE),"")*Classic_Scenarios_Measured[[#This Row],[Scenario Weight]] -> 0 | F32: 0 | G32: =SUM(Classic_Scenarios_Measured[[#This Row],[Adders (W)]], Classic_Scenarios_Measured[[#This Row],[Scorecard (W)]]) -> 0 | H32: =IF(Classic_Scenarios_Measured[[#This Row],[Scorecard (W)]]<>"", SUM(Classic_Scenarios_Measured[[#This Row],[Manual Adder (W)]:[Touch Adder (W)]]), "") | J32: 0.0013 | K32: =IF(OFFSET(Scorecard!$B$15, 0, MATCH(Classic_Scenarios_Measured[[#This Row],[Scenario]], Scorecard!$B$2:$BC$2,0))<>"", OFFSET(Scorecard!$B$15, 0, MATCH(Classic_Scenarios_Measured[[#This Row],[Scenario]], Scorecard!$B$2:$BC$2,0))/1000, "")
A33: =IF(B33<>"",SUMIF(Classic_Scenarios_Measured[Category],Classic_Scenarios_Measured[[#This Row],[Category]],Classic_Scenarios_Measured[Scenario Weight]),"") -> 1 | B33: =IF(C33<>C32,C33,"") -> Communication | C33: Communication | D33: teams_video_1s | E33: =_xlfn.IFNA(VLOOKUP(Classic_Scenarios_Measured[[#This Row],[Category]],Classic_Categories_Measured[],2,FALSE),"")*Classic_Scenarios_Measured[[#This Row],[Scenario Weight]] -> 0.03 | F33: 1 | G33: =SUM(Classic_Scenarios_Measured[[#This Row],[Adders (W)]], Classic_Scenarios_Measured[[#This Row],[Scorecard (W)]]) -> 0 | H33: =IF(Classic_Scenarios_Measured[[#This Row],[Scorecard (W)]]<>"", SUM(Classic_Scenarios_Measured[[#This Row],[Manual Adder (W)]:[Touch Adder (W)]]), "") | J33: 0.0131 | K33: =IF(OFFSET(Scorecard!$B$15, 0, MATCH(Classic_Scenarios_Measured[[#This Row],[Scenario]], Scorecard!$B$2:$BC$2,0))<>"", OFFSET(Scorecard!$B$15, 0, MATCH(Classic_Scenarios_Measured[[#This Row],[Scenario]], Scorecard!$B$2:$BC$2,0))/1000, "")
... A48: =IF(B48<>"",SUMIF(Classic_Scenarios_Measured[Category],Classic_Scenarios_Measured[[#This Row],[Category]],Classic_Scenarios_Measured[Scenario Weight]),"") -> 1 | B48: =IF(C48<>C47,C48,"") -> Mixed | C48: Mixed | D48: abl_act_xs | E48: =_xlfn.IFNA(VLOOKUP(Classic_Scenarios_Measured[[#This Row],[Category]],Classic_Categories_Measured[],2,FALSE),"")*Classic_Scenarios_Measured[[#This Row],[Scenario Weight]] -> 0 | F48: 1 | G48: =SUM(Classic_Scenarios_Measured[[#This Row],[Adders (W)]], Classic_Scenarios_Measured[[#This Row],[Scorecard (W)]]) -> 0 | H48: =IF(Classic_Scenarios_Measured[[#This Row],[Scorecard (W)]]<>"", SUM(Classic_Scenarios_Measured[[#This Row],[Manual Adder (W)]:[Touch Adder (W)]]), "") | J48: 0.18037995 | K48: =IF(OFFSET(Scorecard!$B$15, 0, MATCH(Classic_Scenarios_Measured[[#This Row],[Scenario]], Scorecard!$B$2:$BC$2,0))<>"", OFFSET(Scorecard!$B$15, 0, MATCH(Classic_Scenarios_Measured[[#This Row],[Scenario]], Scorecard!$B$2:$BC$2,0))/1000, "")

Sheet Touch Adder
A1: Scenario | B1: Touch Adder (W)
A2: abl_active_xs | B2: 0.216
A3: edge_1s | B3: 0.251
A4: edge_facebook_2s | B4: 0.379
A5: facebook_1s | B5: 0.287
A6: idle_home_1s | B6: 0
A7: idle_home_2s | B7: 0
A8: idle_home_apm_2s | B8: 0
A9: instagram_1s | B9: 0.287
A10: instagram_2s | B10: 0.337
A11: local_audio_0s | B11: 0
A12: local_video_1s | B12: 0.018
A13: maps_1s | B13: 0
... A30: spotify_2s | B30: 0.018

Sheet Scorecard
B1: =B2 -> abl_act_xs | D1: =D2 -> sspnd_app_cell_0s | F1: =F2 -> sspnd_app_wifi_0s | H1: =H2 -> edge_fb_2s | J1: =J2 -> edge_1s | L1: =L2 -> facebook_1s | N1: =N2 -> idle_home_2s | P1: =P2 -> instagram_1s | R1: =R2 -> instagram_2s | T1: =T2 -> local_audio_0s | V1: =V2 -> local_video_1s | X1: =X2 -> maps_1s | Z1: =Z2 -> minecraft_1s | AB1: =AB2 -> os_nav_2s | AD1: =AD2 -> photo_pre_2s | AF1: =AF2 -> abl_prod_2s | AH1: =AH2 -> sms_1s | AJ1: =AJ2 -> spotify_0s | AL1: =AL2 -> sspnd_idl_apm_0s | AN1: =AN2 -> teams_video_1s | AP1: =AP2 -> video_capture_w_2s | AR1: =AR2 -> voice_0s | AT1: =AT2 -> youtube_1s | AV1: =AV2 -> sspnd_idl_wifi_0s | AX1: =AX2 -> sspnd_idl_cell_0s | AZ1: =AZ2 -> idle_home_1s | BB1: =BB2 -> idle_home_apm_2s
A2: HoBL | B2: abl_act_xs | D2: sspnd_app_cell_0s | F2: sspnd_app_wifi_0s | H2: edge_fb_2s | J2: edge_1s | L2: facebook_1s | N2: idle_home_2s | P2: instagram_1s | R2: instagram_2s | T2: local_audio_0s | V2: local_video_1s | X2: maps_1s | Z2: minecraft_1s | AB2: os_nav_2s | AD2: photo_pre_2s | AF2: abl_prod_2s | AH2: sms_1s | AJ2: spotify_0s | AL2: sspnd_idl_apm_0s | AN2: teams_video_1s | AP2: video_capture_w_2s | AR2: voice_0s | AT2: youtube_1s | AV2: sspnd_idl_wifi_0s | AX2: sspnd_idl_cell_0s | AZ2: idle_home_1s | BB2: idle_home_apm_2s
A3: Sub-system | B3: Target | C3: Measured | D3: Target | E3: Measured | F3: Target | G3: Measured | H3: Target | I3: Measured | J3: Target | K3: Measured | L3: Target | M3: Measured | N3: Target | O3: Measured | P3: Target | Q3: Measured | R3: Target | S3: Measured | T3: Target | U3: Measured | V3: Target | W3: Measured | X3: Target | Y3: Measured | Z3: Target | AA3: Measured | AB3: Target | AC3: Measured | AD3: Target | AE3: Measured | AF3: Target | AG3: Measured | AH3: Target | AI3: Measured | AJ3: Target | AK3: Measured | AL3: Target | AM3: Measured | AN3: Target | AO3: Measured | AP3: Target | AQ3: Measured | AR3: Target | AS3: Measured | AT3: Target | AU3: Measured | AV3: Target | AW3: Measured | AX3: Target | AY3: Measured | AZ3: Target | BA3: Measured | BB3: Target | BC3: Measured
A4: SoC (mW) | B4: 475 | C4: =IFERROR(HLOOKUP(B$2,'Power Summary'!$B$1:$BS$24,MATCH($A4,'Power Summary'!$A:$A,0), FALSE), "") | D4: 20 | E4: =IFERROR(HLOOKUP(D$2,'Power Summary'!$B$1:$BS$24,MATCH($A4,'Power Summary'!$A:$A,0), FALSE), "") | F4: 21.3 | G4: =IFERROR(HLOOKUP(F$2,'Power Summary'!$B$1:$BS$24,MATCH($A4,'Power Summary'!$A:$A,0), FALSE), "") | H4: 525 | I4: =IFERROR(HLOOKUP(H$2,'Power Summary'!$B$1:$BS$24,MATCH($A4,'Power Summary'!$A:$A,0), FALSE), "") | J4: 465.5 | K4: =IFERROR(HLOOKUP(J$2,'Power Summary'!$B$1:$BS$24,MATCH($A4,'Power Summary'!$A:$A,0), FALSE), "") | L4: 350 | M4: =IFERROR(HLOOKUP(L$2,'Power Summary'!$B$1:$BS$24,MATCH($A4,'Power Summary'!$A:$A,0), FALSE), "") | N4: 110 | O4: =IFERROR(HLOOKUP(N$2,'Power Summary'!$B$1:$BS$24,MATCH($A4,'Power Summary'!$A:$A,0), FALSE), "") | P4: 360 | Q4: =IFERROR(HLOOKUP(P$2,'Power Summary'!$B$1:$BS$24,MATCH($A4,'Power Summary'!$A:$A,0), FALSE), "") | R4: 340 | S4: =IFERROR(HLOOKUP(R$2,'Power Summary'!$B$1:$BS$24,MATCH($A4,'Power Summary'!$A:$A,0), FALSE), "") | T4: 160 | U4: =IFERROR(HLOOKUP(T$2,'Power Summary'!$B$1:$BS$24,MATCH($A4,'Power Summary'!$A:$A,0), FALSE), "") | V4: 310 | W4: =IFERROR(HLOOKUP(V$2,'Power Summary'!$B$1:$BS$24,MATCH($A4,'Power Summary'!$A:$A,0), FALSE), "") | X4: 560 | Y4: =IFERROR(HLOOKUP(X$2,'Power Summary'!$B$1:$BS$24,MATCH($A4,'Power Summary'!$A:$A,0), FALSE), "") | Z4: 1400 | AA4: =IFERROR(HLOOKUP(Z$2,'Power Summary'!$B$1:$BS$24,MATCH($A4,'Power Summary'!$A:$A,0), FALSE), "") | AB4: 545 | AC4: =IFERROR(HLOOKUP(AB$2,'Power Summary'!$B$1:$BS$24,MATCH($A4,'Power Summary'!$A:$A,0), FALSE), "") | AD4: 900 | AE4: =IFERROR(HLOOKUP(AD$2,'Power Summary'!$B$1:$BS$24,MATCH($A4,'Power Summary'!$A:$A,0), FALSE), "") | AF4: 590 | AG4: =IFERROR(HLOOKUP(AF$2,'Power Summary'!$B$1:$BS$24,MATCH($A4,'Power Summary'!$A:$A,0), FALSE), "") | AH4: 430 | AI4: =IFERROR(HLOOKUP(AH$2,'Power Summary'!$B$1:$BS$24,MATCH($A4,'Power Summary'!$A:$A,0), FALSE), "") | AJ4: 175 | AK4: =IFERROR(HLOOKUP(AJ$2,'Power Summary'!$B$1:$BS$24,MATCH($A4,'Power Summary'!$A:$A,0), FALSE), "") | AL4: 13 | AM4: =IFERROR(HLOOKUP(AL$2,'Power Summary'!$B$1:$BS$24,MATCH($A4,'Power Summary'!$A:$A,0), FALSE), "") | AN4: 965 | AO4: =IFERROR(HLOOKUP(AN$2,'Power Summary'!$B$1:$BS$24,MATCH($A4,'Power Summary'!$A:$A,0), FALSE), "") | AP4: 1500 | AQ4: =IFERROR(HLOOKUP(AP$2,'Power Summary'!$B$1:$BS$24,MATCH($A4,'Power Summary'!$A:$A,0), FALSE), "") | AR4: 310 | AS4: =IFERROR(HLOOKUP(AR$2,'Power Summary'!$B$1:$BS$24,MATCH($A4,'Power Summary'!$A:$A,0), FALSE), "") | AT4: 300 | AU4: =IFERROR(HLOOKUP(AT$2,'Power Summary'!$B$1:$BS$24,MATCH($A4,'Power Summary'!$A:$A,0), FALSE), "") | AV4: 17 | AW4: =IFERROR(HLOOKUP(AV$2,'Power Summary'!$B$1:$BS$24,MATCH($A4,'Power Summary'!$A:$A,0), FALSE), "") | AX4: 25 | AY4: =IFERROR(HLOOKUP(AX$2,'Power Summary'!$B$1:$BS$24,MATCH($A4,'Power Summary'!$A:$A,0), FALSE), "") | AZ4: 110 | BA4: =IFERROR(HLOOKUP(AZ$2,'Power Summary'!$B$1:$BS$24,MATCH($A4,'Power Summary'!$A:$A,0), FALSE), "") | BB4: 45 | BC4: =IFERROR(HLOOKUP(BB$2,'Power Summary'!$B$1:$BS$24,MATCH($A4,'Power Summary'!$A:$A,0), FALSE), "")
A5: Memory (mW) | B5: 58 | C5: =IFERROR(HLOOKUP(B$2,'Power Summary'!$B$1:$BS$24,MATCH($A5,'Power Summary'!$A:$A,0), FALSE), "") | D5: 8 | E5: =IFERROR(HLOOKUP(D$2,'Power Summary'!$B$1:$BS$24,MATCH($A5,'Power Summary'!$A:$A,0), FALSE), "") | F5: 10 | G5: =IFERROR(HLOOKUP(F$2,'Power Summary'!$B$1:$BS$24,MATCH($A5,'Power Summary'!$A:$A,0), FALSE), "") | H5: 67 | I5: =IFERROR(HLOOKUP(H$2,'Power Summary'!$B$1:$BS$24,MATCH($A5,'Power Summary'!$A:$A,0), FALSE), "") | J5: 66 | K5: =IFERROR(HLOOKUP(J$2,'Power Summary'!$B$1:$BS$24,MATCH($A5,'Power Summary'!$A:$A,0), FALSE), "") | L5: 31 | M5: =IFERROR(HLOOKUP(L$2,'Power Summary'!$B$1:$BS$24,MATCH($A5,'Power Summary'!$A:$A,0), FALSE), "") | N5: 18 | O5: =IFERROR(HLOOKUP(N$2,'Power Summary'!$B$1:$BS$24,MATCH($A5,'Power Summary'!$A:$A,0), FALSE), "") | P5: 49 | Q5: =IFERROR(HLOOKUP(P$2,'Power Summary'!$B$1:$BS$24,MATCH($A5,'Power Summary'!$A:$A,0), FALSE), "") | R5: 52 | S5: =IFERROR(HLOOKUP(R$2,'Power Summary'!$B$1:$BS$24,MATCH($A5,'Power Summary'!$A:$A,0), FALSE), "") | T5: 23 | U5: =IFERROR(HLOOKUP(T$2,'Power Summary'!$B$1:$BS$24,MATCH($A5,'Power Summary'!$A:$A,0), FALSE), "") | V5: 42 | W5: =IFERROR(HLOOKUP(V$2,'Power Summary'!$B$1:$BS$24,MATCH($A5,'Power Summary'!$A:$A,0), FALSE), "") | X5: 75 | Y5: =IFERROR(HLOOKUP(X$2,'Power Summary'!$B$1:$BS$24,MATCH($A5,'Power Summary'!$A:$A,0), FALSE), "") | Z5: 320 | AA5: =IFERROR(HLOOKUP(Z$2,'Power Summary'!$B$1:$BS$24,MATCH($A5,'Power Summary'!$A:$A,0), FALSE), "") | AB5: 58 | AC5: =IFERROR(HLOOKUP(AB$2,'Power Summary'!$B$1:$BS$24,MATCH($A5,'Power Summary'!$A:$A,0), FALSE), "") | AD5: 250 | AE5: =IFERROR(HLOOKUP(AD$2,'Power Summary'!$B$1:$BS$24,MATCH($A5,'Power Summary'!$A:$A,0), FALSE), "") | AF5: 59 | AG5: =IFERROR(HLOOKUP(AF$2,'Power Summary'!$B$1:$BS$24,MATCH($A5,'Power Summary'!$A:$A,0), FALSE), "") | AH5: 48 | AI5: =IFERROR(HLOOKUP(AH$2,'Power Summary'!$B$1:$BS$24,MATCH($A5,'Power Summary'!$A:$A,0), FALSE), "") | AJ5: 25 | AK5: =IFERROR(HLOOKUP(AJ$2,'Power Summary'!$B$1:$BS$24,MATCH($A5,'Power Summary'!$A:$A,0), FALSE), "") | AL5: 8 | AM5: =IFERROR(HLOOKUP(AL$2,'Power Summary'!$B$1:$BS$24,MATCH($A5,'Power Summary'!$A:$A,0), FALSE), "") | AN5: 280 | AO5: =IFERROR(HLOOKUP(AN$2,'Power Summary'!$B$1:$BS$24,MATCH($A5,'Power Summary'!$A:$A,0), FALSE), "") | AP5: 250 | AQ5: =IFERROR(HLOOKUP(AP$2,'Power Summary'!$B$1:$BS$24,MATCH($A5,'Power Summary'!$A:$A,0), FALSE), "") | AR5: 76 | AS5: =IFERROR(HLOOKUP(AR$2,'Power Summary'!$B$1:$BS$24,MATCH($A5,'Power Summary'!$A:$A,0), FALSE), "") | AT5: 42 | AU5: =IFERROR(HLOOKUP(AT$2,'Power Summary'!$B$1:$BS$24,MATCH($A5,'Power Summary'!$A:$A,0), FALSE), "") | AV5: 9 | AW5: =IFERROR(HLOOKUP(AV$2,'Power Summary'!$B$1:$BS$24,MATCH($A5,'Power Summary'!$A:$A,0), FALSE), "") | AX5: 10 | AY5: =IFERROR(HLOOKUP(AX$2,'Power Summary'!$B$1:$BS$24,MATCH($A5,'Power Summary'!$A:$A,0), FALSE), "") | AZ5: 22 | BA5: =IFERROR(HLOOKUP(AZ$2,'Power Summary'!$B$1:$BS$24,MATCH($A5,'Power Summary'!$A:$A,0), FALSE), "") | BB5: 18 | BC5: =IFERROR(HLOOKUP(BB$2,'Power Summary'!$B$1:$BS$24,MATCH($A5,'Power Summary'!$A:$A,0), FALSE), "")
A6: Display (mW) | B6: 825.88235 | C6: =IFERROR(HLOOKUP(B$2,'Power Summary'!$B$1:$BS$24,MATCH($A6,'Power Summary'!$A:$A,0), FALSE), "") | D6: 5.5076786 | E6: =IFERROR(HLOOKUP(D$2,'Power Summary'!$B$1:$BS$24,MATCH($A6,'Power Summary'!$A:$A,0), FALSE), "") | F6: 5.5076786 | G6: =IFERROR(HLOOKUP(F$2,'Power Summary'!$B$1:$BS$24,MATCH($A6,'Power Summary'!$A:$A,0), FALSE), "") | H6: 1150.8824 | I6: =IFERROR(HLOOKUP(H$2,'Power Summary'!$B$1:$BS$24,MATCH($A6,'Power Summary'!$A:$A,0), FALSE), "") | J6: 480.29412 | K6: =IFERROR(HLOOKUP(J$2,'Power Summary'!$B$1:$BS$24,MATCH($A6,'Power Summary'!$A:$A,0), FALSE), "") | L6: 624.41176 | M6: =IFERROR(HLOOKUP(L$2,'Power Summary'!$B$1:$BS$24,MATCH($A6,'Power Summary'!$A:$A,0), FALSE), "") | N6: 798.52941 | O6: =IFERROR(HLOOKUP(N$2,'Power Summary'!$B$1:$BS$24,MATCH($A6,'Power Summary'!$A:$A,0), FALSE), "") | P6: 394.41176 | Q6: =IFERROR(HLOOKUP(P$2,'Power Summary'!$B$1:$BS$24,MATCH($A6,'Power Summary'!$A:$A,0), FALSE), "") | R6: 822.58824 | S6: =IFERROR(HLOOKUP(R$2,'Power Summary'!$B$1:$BS$24,MATCH($A6,'Power Summary'!$A:$A,0), FALSE), "") | T6: 5.5076786 | U6: =IFERROR(HLOOKUP(T$2,'Power Summary'!$B$1:$BS$24,MATCH($A6,'Power Summary'!$A:$A,0), FALSE), "") | V6: 265.88235 | W6: =IFERROR(HLOOKUP(V$2,'Power Summary'!$B$1:$BS$24,MATCH($A6,'Power Summary'!$A:$A,0), FALSE), "") | X6: 729.88235 | Y6: =IFERROR(HLOOKUP(X$2,'Power Summary'!$B$1:$BS$24,MATCH($A6,'Power Summary'!$A:$A,0), FALSE), "") | Z6: 443.15503 | AA6: =IFERROR(HLOOKUP(Z$2,'Power Summary'!$B$1:$BS$24,MATCH($A6,'Power Summary'!$A:$A,0), FALSE), "") | AB6: 770.58824 | AC6: =IFERROR(HLOOKUP(AB$2,'Power Summary'!$B$1:$BS$24,MATCH($A6,'Power Summary'!$A:$A,0), FALSE), "") | AD6: 700 | AE6: =IFERROR(HLOOKUP(AD$2,'Power Summary'!$B$1:$BS$24,MATCH($A6,'Power Summary'!$A:$A,0), FALSE), "") | AF6: 1310.6554 | AG6: =IFERROR(HLOOKUP(AF$2,'Power Summary'!$B$1:$BS$24,MATCH($A6,'Power Summary'!$A:$A,0), FALSE), "") | AH6: 309.41176 | AI6: =IFERROR(HLOOKUP(AH$2,'Power Summary'!$B$1:$BS$24,MATCH($A6,'Power Summary'!$A:$A,0), FALSE), "") | AJ6: 5.5076786 | AK6: =IFERROR(HLOOKUP(AJ$2,'Power Summary'!$B$1:$BS$24,MATCH($A6,'Power Summary'!$A:$A,0), FALSE), "") | AL6: 5.5076786 | AM6: =IFERROR(HLOOKUP(AL$2,'Power Summary'!$B$1:$BS$24,MATCH($A6,'Power Summary'!$A:$A,0), FALSE), "") | AN6: 397.41176 | AO6: =IFERROR(HLOOKUP(AN$2,'Power Summary'!$B$1:$BS$24,MATCH($A6,'Power Summary'!$A:$A,0), FALSE), "") | AP6: 700 | AQ6: =IFERROR(HLOOKUP(AP$2,'Power Summary'!$B$1:$BS$24,MATCH($A6,'Power Summary'!$A:$A,0), FALSE), "") | AR6: 0.20117647 | AS6: =IFERROR(HLOOKUP(AR$2,'Power Summary'!$B$1:$BS$24,MATCH($A6,'Power Summary'!$A:$A,0), FALSE), "") | AT6: 297.88235 | AU6: =IFERROR(HLOOKUP(AT$2,'Power Summary'!$B$1:$BS$24,MATCH($A6,'Power Summary'!$A:$A,0), FALSE), "") | AV6: 5.5076786 | AW6: =IFERROR(HLOOKUP(AV$2,'Power Summary'!$B$1:$BS$24,MATCH($A6,'Power Summary'!$A:$A,0), FALSE), "") | AX6: 5.5076786 | AY6: =IFERROR(HLOOKUP(AX$2,'Power Summary'!$B$1:$BS$24,MATCH($A6,'Power Summary'!$A:$A,0), FALSE), "") | AZ6: 401.70977 | BA6: =IFERROR(HLOOKUP(AZ$2,'Power Summary'!$B$1:$BS$24,MATCH($A6,'Power Summary'!$A:$A,0), FALSE), "") | BB6: 798.52941 | BC6: =IFERROR(HLOOKUP(BB$2,'Power Summary'!$B$1:$BS$24,MATCH($A6,'Power Summary'!$A:$A,0), FALSE), "")
